

<mujoco model="walter">

    <!--Defining the assets for the model-->
  <asset>
    <texture type="skybox" builtin="gradient" rgb1="1 1 1" rgb2=".6 .8 1" width="256" height="256"/>
    <mesh name = "thigh_mesh" file = "assets/Thigh.stl"/>
    <mesh name = "shin_mesh" file = "assets/Shin.stl"/>
    <mesh name = "wheel_mesh" file = "assets/Wheel.stl"/>
    <mesh name = "body_mesh" file = "assets/Body.stl"/>
    <mesh name = "head_mesh" file = "assets/Head.stl"/>
  </asset>

  <!--Defining default classes for components-->
  <default>
    <geom rgba="0.89 0.78 0.6 1"/>
    <joint armature="0.019764"/>


    <!-- Default thigh class -->
    <default class="thigh">
        <geom type="mesh" mesh="thigh_mesh"/>
    </default> 

    <!-- Default shin class -->
    <default class="shin">
        <geom type="mesh" mesh="shin_mesh"/>
    </default>

    <!-- Default wheel class -->
    <default class="wheel">
        <geom type="mesh" mesh="wheel_mesh"/>
    </default>

  </default>

  <!-- WALTER MODEL -->
    <worldbody>
        <light diffuse=".5 .5 .5" pos="0 0 3" dir="0 0 -1"/>
        <!-- Rear Body Section -->
        <body name="body" pos="0 0 0.4">
            <joint type="free"/>
            <geom type="mesh" mesh = "body_mesh" />
            <!-- Add rear legs here -->

            <!-- Back left thigh -->
             <body name = "bl_thigh" pos = "-0.274 0.075 -0.031" quat = "0 0 1 1">
                <inertial pos = "0 -0.05 0.03" mass = "0.20157" diaginertia="0.0005212 0.000114 0.0005585"/>
                <joint name="bl_hip" type="hinge" axis = "0 0 1" />
                <geom class="thigh"/>
                <!-- Back left shin -->
                <body name = "bl_shin" pos = "0 -0.1 0.043" >
                    <joint name="bl_knee" type="hinge" axis = "0 0 1"/>
                    <geom class="shin"/>
                    <!-- Back left wheels -->
                     <body name = "bl_wheel1" pos = "0.08 0 0.088">
                        <geom class="wheel"/>
                        <joint name="bl_wheel1_joint" type="hinge" axis="0 0 1"/>
                     </body>
                     <body name = "bl_wheel2" pos = "-0.08 0 0.088">
                        <geom class="wheel"/>
                        <joint name="bl_wheel2_joint" type="hinge" axis="0 0 1"/>
                     </body>
                </body>
             </body>

            
            <!-- Back right thigh -->
            <body name = "br_thigh" pos = "-0.274 -0.075 -0.031" quat = "1 1 0 0">
                <inertial pos = "0 -0.05 0.03" mass = "0.20157" diaginertia="0.0005212 0.000114 0.0005585"/>
                <joint name="br_hip" type="hinge" axis = "0 0 1" />
                <geom class="thigh"/>
                <!-- Back right shin -->
                <body name = "br_shin" pos = "0 -0.1 0.043" >
                    <joint name="br_knee" type="hinge" axis = "0 0 1"/>
                    <geom class="shin"/>
                    <!-- Back right wheels -->
                     <body name = "br_wheel1" pos = "0.08 0 0.088">
                        <geom class="wheel"/>
                        <joint name="br_wheel1_joint" type="hinge" axis="0 0 1"/>
                     </body>
                     <body name = "br_wheel2" pos = "-0.08 0 0.088">
                        <geom class="wheel"/>
                        <joint name="br_wheel2_joint" type="hinge" axis="0 0 1"/>
                     </body>
                </body>
             </body>



            <!-- Front Body Section -->
            <body name="head" pos="0.01 0 0">
                <joint name="body_joint" type="hinge" axis = "1 0 0"/>
                <geom type="mesh" mesh = "head_mesh"/>

                <!-- Add front legs here -->
                 <!-- Front left thigh -->
                 <body name = "fl_thigh" pos = "0.094 0.075 -0.031" quat = "0 0 1 1">
                    <inertial pos = "0 -0.05 0.03" mass = "0.20157" diaginertia="0.0005212 0.000114 0.0005585"/>
                    <joint name="fl_hip" type="hinge" axis = "0 0 1" />
                    <geom class="thigh"/>
                    <!-- Back left shin -->
                    <body name = "fl_shin" pos = "0 -0.1 0.043" >
                        <joint name="fl_knee" type="hinge" axis = "0 0 1"/>
                        <geom class="shin"/>
                        <!-- Back left wheels -->
                         <body name = "fl_wheel1" pos = "0.08 0 0.088">
                            <geom class="wheel"/>
                            <joint name="fl_wheel1_joint" type="hinge" axis="0 0 1"/>
                         </body>
                         <body name = "fl_wheel2" pos = "-0.08 0 0.088">
                            <geom class="wheel"/>
                            <joint name="fl_wheel2_joint" type="hinge" axis="0 0 1"/>
                         </body>
                    </body>
                 </body>

                <!-- Front right thigh -->
                <body name = "fr_thigh" pos = "0.094 -0.075 -0.031" quat = "1 1 0 0">
                    <inertial pos = "0 -0.05 0.03" mass = "0.20157" diaginertia="0.0005212 0.000114 0.0005585"/>
                    <joint name="fr_hip" type="hinge" axis = "0 0 1" />
                    <geom class="thigh"/>
                    <!-- Back left shin -->
                    <body name = "fr_shin" pos = "0 -0.1 0.043" >
                        <joint name="fr_knee" type="hinge" axis = "0 0 1"/>
                        <geom class="shin"/>
                        <!-- Back left wheels -->
                            <body name = "fr_wheel1" pos = "0.08 0 0.088">
                                <geom class="wheel"/>
                                <joint name="fr_wheel1_joint" type="hinge" axis="0 0 1"/>
                            </body>
                            <body name = "fr_wheel2" pos = "-0.08 0 0.088">
                                <geom class="wheel"/>
                                <joint name="fr_wheel2_joint" type="hinge" axis="0 0 1"/>
                            </body>
                    </body>
                </body>
            </body> 

        </body>
    </worldbody>
    <!-- Defining the actuators -->
    <actuator>
        <position joint="fr_hip"/>
        <position joint="fr_knee"/>
        <position joint="fr_wheel1_joint"/>
        <position joint="fr_wheel2_joint"/>
        <position joint="fl_hip"/>
        <position joint="fl_knee"/>
        <position joint="fl_wheel1_joint"/>
        <position joint="fl_wheel2_joint"/>
        <position joint="br_hip"/>
        <position joint="br_knee"/>
        <position joint="br_wheel1_joint"/>
        <position joint="br_wheel2_joint"/>
        <position joint="bl_hip"/>
        <position joint="bl_knee"/>
        <position joint="bl_wheel1_joint"/>
        <position joint="bl_wheel2_joint"/>
    </actuator>
    <!-- <keyframe>
    <key name="home"
        qpos="0 0 0.28
            1 0 0 0
            0.0 0.5 1.0
            0.0 0.5 1.0
            0.0 0.5 1.0
            0.0 0.5 1.0
            0.0 0.5 1.0
            0.0 0.5"
        ctrl="0 0 0 0
             0 0 0 0
             0 0 0 0
             0 0 0 0"/>
    </keyframe> -->
</mujoco>
